<?xml version="1.0"?>
<robot name="gripper_scara" xmlns:xacro="http://www.ros.org/wiki/xacro">

<material name="blue"><color rgba="0 0 1 1"/></material>
<material name="green"><color rgba="0 1 0 1"/></material>
<material name="yellow"><color rgba="1 1 0 1"/></material>
<material name="orange"><color rgba="1 0.5 0 1"/></material>
<material name="purple"><color rgba="0.5 0 0.5 1"/></material>
<material name="red"><color rgba="1 0 0 1"/></material>

<link name="base_footprint"/>

<!-- BASE LINK -->
<link name="gripper_base_link">
  <visual>
    <geometry>
      <mesh filename="file:///home/linos/cad_projects/gripper/base.stl" scale="0.001 0.001 0.001"/>
    </geometry>
    <origin xyz="0 ${0.0402/2} ${0.04-0.01}" rpy="${pi} 0 0"/>
    <material name="blue"/>
  </visual>

  <collision>
    <origin xyz="0.04 ${0.0402/2-0.02} ${0.02}" rpy="${pi} 0 0"/>
    <geometry>
      <cylinder radius="${0.06}" length="0.06"/>
    </geometry>
  </collision>

  <collision>
    <origin xyz="0.008 0 0.21" rpy="${pi} 0 0"/>
    <geometry>
      <box size="0.06 0.1 0.317"/>
    </geometry>
  </collision>

  <inertial>
    <!-- match the main collision frame rotation -->
    <origin xyz="0.0164 0.0 0.16" rpy="${pi} 0 0"/>
    <mass value="3.0"/>
    <inertia
      ixx="0.0353"
      iyy="0.0348"
      izz="0.00377"
      ixy="0.0" ixz="0.0" iyz="0.0"/>
  </inertial>
</link>

<!-- SLIDER -->
<link name="slider_carriage_link">
  <visual>
    <geometry>
      <mesh filename="file:///home/linos/cad_projects/gripper/slider_carriage.stl" scale="0.001 0.001 0.001"/>
    </geometry>
    <origin xyz="0 ${-0.0342/2} ${0.253}" rpy="0 0 0"/>
    <material name="green"/>
  </visual>

  <collision>
    <geometry>
      <box size="0.06 0.04 0.07"/>
    </geometry>
    <origin xyz="0.07 0 0.01" rpy="0 0 0"/>
  </collision>

  <inertial>
    <origin xyz="0.07 0 0.01" rpy="0 0 0"/>
    <mass value="0.6"/>
    <inertia
      ixx="0.000325"
      iyy="0.000425"
      izz="0.00026"
      ixy="0.0" ixz="0.0" iyz="0.0"/>
  </inertial>
</link>

<!-- SHOULDER -->
<link name="shoulder_link">
  <visual>
    <geometry>
      <mesh filename="file:///home/linos/cad_projects/gripper/shoulder.stl" scale="0.001 0.001 0.001"/>
    </geometry>
    <origin xyz="-0.08 ${-0.0342/2} 0.253" rpy="0 0 0"/>
    <material name="yellow"/>
  </visual>

  <collision>
    <geometry>
      <box size="0.123 0.0235 0.066"/>
    </geometry>
    <origin xyz="0.06 0.03 0.01" rpy="0 0 ${pi/7}"/>
  </collision>

  <inertial>
    <origin xyz="0.06 0.03 0.01" rpy="0 0 ${pi/7}"/>
    <mass value="0.5"/>
    <inertia
      ixx="0.000205"
      iyy="0.000812"
      izz="0.000653"
      ixy="0.0" ixz="0.0" iyz="0.0"/>
  </inertial>
</link>

<!-- ELBOW -->
<link name="elbow_link">
  <visual>
    <geometry>
      <mesh filename="file:///home/linos/cad_projects/gripper/elbow.stl" scale="0.001 0.001 0.001"/>
    </geometry>
    <origin xyz="-0.18 -0.047 0.253" rpy="0 0 0"/>
    <material name="orange"/>
  </visual>

  <collision>
    <geometry>
      <box size="0.123 0.027 0.066"/>
    </geometry>
    <origin xyz="0.016 -0.05 0.01" rpy="0 0 -1.25"/>
  </collision>

  <inertial>
    <origin xyz="0.016 -0.05 0.01" rpy="0 0 -1.25"/>
    <mass value="0.4"/>
    <inertia
      ixx="0.000170"
      iyy="0.000650"
      izz="0.000529"
      ixy="0.0" ixz="0.0" iyz="0.0"/>
  </inertial>
</link>

<!-- WRIST -->
<link name="wrist_link">
  <visual>
    <geometry>
      <mesh filename="file:///home/linos/cad_projects/gripper/wrist.stl" scale="0.001 0.001 0.001"/>
    </geometry>
    <origin xyz="-0.0275 -0.02 -0.03" rpy="${-pi/2} 0 0"/>
    <material name="purple"/>
  </visual>

  <collision>
    <geometry>
      <box size="0.055 0.06 0.04"/>
    </geometry>
    <origin xyz="0 0 -0.02" rpy="${-pi/2} 0 0"/>
  </collision>

  <inertial>
    <origin xyz="0 0 -0.02" rpy="${-pi/2} 0 0"/>
    <mass value="0.4"/>
    <inertia
      ixx="0.000108"
      iyy="0.000096"
      izz="0.000138"
      ixy="0.0" ixz="0.0" iyz="0.0"/>
  </inertial>
</link>

<!-- LEFT FINGER -->
<link name="left_finger_link">
  <visual>
    <geometry>
      <mesh filename="file:///home/linos/cad_projects/gripper/left_finger.stl" scale="0.001 0.001 0.001"/>
    </geometry>
    <origin xyz="0.16 0.117 -0.155" rpy="0 ${pi} ${pi/12}"/>
    <material name="red"/>
  </visual>

  <collision>
    <geometry>
      <box size="0.017 0.037 0.04"/>
    </geometry>
    <origin xyz="0 0.02 -0.02" rpy="0 ${pi} 0"/>
  </collision>

  <inertial>
    <origin xyz="0 0.02 -0.02" rpy="0 ${pi} 0"/>
    <mass value="0.08"/>
    <inertia
      ixx="0.0000198"
      iyy="0.0000126"
      izz="0.0000111"
      ixy="0.0" ixz="0.0" iyz="0.0"/>
  </inertial>
</link>

<!-- RIGHT FINGER -->
<link name="right_finger_link">
  <visual>
    <geometry>
      <mesh filename="file:///home/linos/cad_projects/gripper/right_finger.stl" scale="0.001 0.001 0.001"/>
    </geometry>
    <origin xyz="0.215 0.117 -0.155" rpy="0 ${pi} ${pi/12}"/>
    <material name="red"/>
  </visual>

  <collision>
    <geometry>
      <box size="0.017 0.037 0.04"/>
    </geometry>
    <origin xyz="0 0.02 -0.02" rpy="0 ${pi} 0"/>
  </collision>

  <inertial>
    <origin xyz="0 0.02 -0.02" rpy="0 ${pi} 0"/>
    <mass value="0.08"/>
    <inertia
      ixx="0.0000198"
      iyy="0.0000126"
      izz="0.0000111"
      ixy="0.0" ixz="0.0" iyz="0.0"/>
  </inertial>
</link>

<!-- JOINTS (unchanged) -->
<joint name="base_to_footprint" type="fixed">
  <parent link="base_footprint"/>
  <child link="gripper_base_link"/>
  <origin xyz="0 0 0" rpy="0 0 0"/>
</joint>

<joint name="slider_to_base" type="prismatic">
  <parent link="gripper_base_link"/>
  <child link="slider_carriage_link"/>
  <origin xyz="0 0 ${0.253}" rpy="0 0 0"/>
  <axis xyz="0 0 1"/>
  <limit lower="0" upper="-0.15" effort="50" velocity="0.1"/>
</joint>

<joint name="shoulder_to_slider" type="revolute">
  <parent link="slider_carriage_link"/>
  <child link="shoulder_link"/>
  <origin xyz="0.08 0 ${0.263/2 -0.1315}" rpy="0 0 0"/>
  <axis xyz="0 0 1"/>
  <limit lower="${-pi/2}" upper="${pi/4}" effort="50" velocity="1.0"/>
</joint>

<joint name="elbow_to_shoulder" type="revolute">
  <parent link="shoulder_link"/>
  <child link="elbow_link"/>
  <origin xyz="0.095 0.047 0" rpy="0 0 0"/>
  <axis xyz="0 0 1"/>
  <limit lower="${0}" upper="${3.343}" effort="50" velocity="1.0"/>
</joint>

<joint name="wrist_to_elbow" type="revolute">
  <parent link="elbow_link"/>
  <child link="wrist_link"/>
  <origin xyz="0.025 -0.088 0" rpy="0 0 0"/>
  <axis xyz="0 0 1"/>
  <limit lower="${-pi/2}" upper="${pi/2}" effort="50" velocity="1.0"/>
</joint>

<joint name="left_finger_to_wrist" type="prismatic">
  <parent link="wrist_link"/>
  <child link="left_finger_link"/>
  <origin xyz="0.0275 -0.02 -0.05" rpy="0 0 0"/>
  <axis xyz="1 0 0"/>
  <limit lower="-0.015" upper="0.015" effort="20" velocity="0.05"/>
</joint>

<joint name="right_finger_to_wrist" type="prismatic">
  <parent link="wrist_link"/>
  <child link="right_finger_link"/>
  <origin xyz="-0.02 -0.02 -0.05" rpy="0 0 0"/>
  <axis xyz="1 0 0"/>
  <limit lower="-0.015" upper="0.015" effort="20" velocity="0.05"/>
</joint>

</robot>
